Workbook

Sheet ESTIMATE
A1: SI.NO | B1: Description of works | C1: Unit | D1: Quantity | E1: Rate | F1: Amount
A2: 1 | B2: Earthwork in excavation in ordinary soils including filled up area, in both Dry and Wet conditions, including Pumping and Bailing out Surface and Subsoil water, rain water by using any suitable dewatering method, Slush, muck removal, sorting out the excavated earth into serviceable and unserviceable material, Including backfilling. The cost include transportation of both unserviceable/ serviceable material into dumping yards or wherever required as per direction of Engineer incharge upto any lead within plant boundary . The rate also inclusive of marking the Road layout by means of Total Station with Corresponding co-ordinates and measurements at site. The Contractor shall take into account in his rate, the provision for excess excavation for necessary working space, side slope and backfilling the same. Existing ground level/T.L shall be recorded jointly before starting of excavation. All survey equipment (like dumpy level etc) shall be arranged by contractor at his own cost. Cost towards dewatering of surface or subsoil water shall be deemed to have included in the quoted rate. | C2: CUM | D2: ='m sheet'!H6 -> 23.3376 | E2: 350 | F2: =E2*D2 -> 8168.16
A3: 2 | B3: Supply of Available sand (filling purpose)The rate shall include all material, labours, machinery and tools and tackles,consumobels etc., complete and as per specifications, drawings and directions of the Engineer-In Charge… | C3: CUM | D3: ='m sheet'!H8 -> 11.3904 | E3: 1600 | F3: =E3*D3 -> 18224.64
A4: 3 | B4: Providing and laying Of GSB (Granular sub Base) by providing close grade material, spreading uniform layers on prepare surface mixing by mix place method and compacting with earth rammer to achive desired density As per clause 401 on Most Spec. The rate shall include all material, labours, machinery and tools and tackles,consumobels etc., complete and as per specifications, drawings and directions of the Engineer-In Charge... | C4: CUM | D4: ='m sheet'!H16 -> 9.0168 | E4: 2600 | F4: =E4*D4 -> 23443.68
A5: 4 | B5: Supplying and Laying Plain Cement Concrete of following Grades (including Shuttering if required) in all levelling courses under Foundation, pile cap, apron, drains, steps, Floors, coping, Pits etc., at all depths complete all as per Drawings and Specifications and instruction of the Engineer. The rate also inclusive of marking the Foundation layout by means of Total Station with Corresponding co -ordinates and measurements at site. M-15 Grade of Concrete,using Ordinary portland cement (CA content 5 to 8%& 40 mm down graded coarse aggregate. | C5: CUM | D5: ='m sheet'!H25 -> 8.1126 | E5: 6800 | F5: =E5*D5 -> 55165.68
A6: 5 | B6: Supplying and Laying of Reinforced Cement Concrete of M30 Grade (Excluding Shuttering and excluding reinforcement) at all depths and heights in all types of Foundations, Pile cap, equipment foundations, columns and any other works both in Sub and Superstructures all complete as per Drawings, Specification and instruction of Engineer. The rate also inclusive of marking the Foundation/Pedestal Layout at site. (Using Cement brand Chettinad/ Dalmia/ Coromandel - OPC 53 Grade (with C3A content limited to 5% to 8%) with minimum cement content per Cum of concrete to be not less than 400 kg) (Dispensary Grade slab) | C6: CUM | D6: ='m sheet'!H33 -> 2.78208 | E6: 8600 | F6: =E6*D6 -> 23925.888
A7: 6 | B7: Providing, Fixing and Stripping of Shuttering of good quality plywood or steel plate on steel frame for all types of Structures not covered in respective items including Centering / Scaffolding, all complete as per Drawings, Specifications and directions of the Engineer. | C7: SQM | D7: ='m sheet'!H39 -> 24.192 | E7: 650 | F7: =E7*D7 -> 15724.8
A8: 7 | B8: Providing and constructing 230 mm thick brick masonry in CM 1:5 (1 cement: 5 coarse sand) with approved good quality fly ash bricks for all types of structures and at all levels. The rate shall include cost of all materials, labor charges, curing, scaffoldings, tools & tackles, transportations, etc., complete and as directed by the Engineer - in - charge. | C8: CUM | D8: ='m sheet'!H55 -> 31.86697 | E8: 8900 | F8: =E8*D8 -> 283616.03
A9: 8 | B9: Providing and applying 12 mm thick Plastering in CM 1:4 for internal & External wall surfaces, beams, sills door/ window jams etc. in all levels including finishing the surfaces smoothly. The rate shall include all materials, Chicken mesh, labor charges, tools & tackles, transportations, curing, scaffoldings, etc., complete and as directed by the Engineer - in - charge. | C9: SQM | D9: ='m sheet'!H75 -> 205.641 | E9: 575 | F9: =E9*D9 -> 118243.57
A10: 9 | B10: Finishing with tractor emulsion paint (Asian paint) of approved brand and manufacturer of required colour to give an even shade all complete as per drawings, specifications and/or as directed by the engineer. For internal wall & External wall. | C10: SQM | D10: ='m sheet'!H94 -> 184.041 | E10: 260 | F10: =E10*D10 -> 47850.66
A11: 10 | B11: Supplying and Fabricating and Fixing in position Steel Reinforcements at all levels and positions including the Cost of transport, straightening, Cutting, Bending, Cranking, Binding, Welding, Provision of necessary Chairs and Spacers, Preparation of bar bending schedule Drawings, getting the same approved etc., as per Drawings and Specifications and including Cost of binding wire, Labour etc., all complete for Reinforced concrete and reinforced brick work and any other place as specified below. The chairs and spacer bars provided will not be Measured for payment. | C11: MT | D11: 0.38 | E11: 79000 | F11: =E11*D11 -> 30020
A12: 11 | F12: =E12*D12 -> 0
A13: 11 | B13: Provided Aluminium powder quoted grill for windows | C13: nos | D13: 5 | E13: 1500 | F13: =E13*D13 -> 7500
A14: 12 | B14: Jally fixing in position | C14: nos | D14: 2 | E14: 500 | F14: =E14*D14 -> 1000
A15: 13 | B15: Granite fixing in position with including cutting fixing polishing | C15: sqm | D15: 5.93 | E15: 4850 | F15: =E15*D15 -> 28760.5
A16: 14 | B16: Plumbing | F16: =E16*D16 -> 0
A17: a | B17: Ball valve | C17: nos | D17: 3 | E17: 428 | F17: =E17*D17 -> 1284
A18: b | B18: EWC | C18: nos | D18: 2 | E18: 13500 | F18: =E18*D18 -> 27000
A19: c | B19: IWC | C19: nos | D19: 2 | E19: 13500 | F19: =E19*D19 -> 27000
A20: d | B20: Urinal | C20: nos | D20: 7 | E20: 7600 | F20: =E20*D20 -> 53200
A21: e | B21: U pvc pipe -40mm | C21: Rmt | D21: 29.3 | E21: 415 | F21: =E21*D21 -> 12159.5
A22: f | B22: pvc pipe -75mm | C22: Rmt | D22: 12 | E22: 400 | F22: =E22*D22 -> 4800
A23: g | B23: Bath 40mm pvc pipe | C23: Rmt | D23: 14.1 | E23: 415 | F23: =E23*D23 -> 5851.5
A24: h | B24: Pvc pipe 110mm | C24: Rmt | D24: 15 | E24: 515 | F24: =E24*D24 -> 7725
A25: i | B25: Floor trap with fixing in levels | C25: nos | D25: 5 | E25: 600 | F25: =E25*D25 -> 3000
A26: 15 | B26: PVC door for restroom | C26: nos | D26: 5 | E26: 4400 | F26: =E26*D26 -> 22000
A27: 16 | B27: Steel door for main door | C27: Ls | D27: 1 | E27: 5000 | F27: =E27*D27 -> 5000
A28: 17 | B28: Roof sheet fixing work including labour, tools & tackles | C28: sqm | D28: 35.38 | E28: 110 | F28: =E28*D28 -> 3891.8
A29: 18 | B29: Providing and fixing of Precast Septic tank including erection, transportation and Earthwork | C29: nos | D29: 16 | E29: 2250 | F29: =E29*D29 -> 36000
B30: TOTAL AMOUNT | C30: RS | F30: =SUM(F2:F29) -> 870555.42

Sheet m sheet
A1: VVC Toilet Unit-2
A2: Sl.NO | B2: DESCRIPITION OF WORK | C2: NOS | E2: LENGTH | F2: BREADTH | G2: DEPTH | H2: QUANTITY | I2: REMARKS
A4: 1 | B4: Earth work excavation | C4: 1 | D4: 2 | E4: 7.1 | F4: 1.43 | G4: 0.6 | H4: =G4*F4*E4*D4*C4 -> 12.1836
C5: 1 | D5: 2 | E5: 6.5 | F5: 1.43 | G5: 0.6 | H5: =G5*F5*E5*D5*C5 -> 11.154
G6: Total | H6: =SUM(H4:H5) -> 23.3376
A7: 2 | B7: Soil filling
C8: 1 | D8: 1 | E8: 5.65 | F8: 5.04 | G8: 0.4 | H8: =G8*F8*E8*D8*C8 -> 11.3904
A11: 3 | B11: GSB
B12: Outer basement | C12: 1 | D12: 2 | E12: 6.4 | F12: 0.63 | G12: 0.2 | H12: =G12*F12*E12*D12*C12 -> 1.6128
B13: Outer basement | C13: 1 | D13: 2 | E13: 5.9 | F13: 0.63 | G13: 0.2 | H13: =G13*F13*E13*D13*C13 -> 1.4868
B14: Flooring | C14: 1 | D14: 1 | E14: 5.65 | F14: 5.04 | G14: 0.2 | H14: =G14*F14*E14*D14*C14 -> 5.6952
B15: Steps | C15: 1 | D15: 1 | E15: 1.85 | F15: 0.6 | G15: 0.2 | H15: =G15*F15*E15*D15*C15 -> 0.222
G16: Total | H16: =SUM(H12:H15) -> 9.0168
A19: 4 | B19: PCC
B20: Outer basement | C20: 1 | D20: 2 | E20: 6.4 | F20: 0.63 | G20: 0.15 | H20: =G20*F20*E20*D20*C20 -> 1.2096
B21: Outer basement | C21: 1 | D21: 2 | E21: 5.9 | F21: 0.63 | G21: 0.15 | H21: =G21*F21*E21*D21*C21 -> 1.1151
B22: Flooring | C22: 1 | D22: 1 | E22: 5.65 | F22: 5.04 | G22: 0.15 | H22: =G22*F22*E22*D22*C22 -> 4.2714
B23: Steps | C23: 1 | D23: 1 | E23: 1.85 | F23: 0.6 | G23: 0.15 | H23: =G23*F23*E23*D23*C23 -> 0.1665
B24: Tank | C24: 2 | D24: 1 | E24: 3 | F24: 1.5 | G24: 0.15 | H24: =G24*F24*E24*D24*C24 -> 1.35
G25: Total | H25: =SUM(H20:H24) -> 8.1126
A29: 5 | B29: Plinth beam
B30: Long outer beam | C30: 1 | D30: 2 | E30: 6.1 | F30: 0.23 | G30: 0.45 | H30: =G30*F30*E30*D30*C30 -> 1.2627
B31: Short outer beam | C31: 1 | D31: 2 | E31: 5.5 | F31: 0.23 | G31: 0.45 | H31: =G31*F31*E31*D31*C31 -> 1.1385
B32: Centre partition beam | C32: 1 | D32: 4 | E32: 1.8 | F32: 0.23 | G32: 0.23 | H32: =G32*F32*E32*D32*C32 -> 0.38088
G33: Total | H33: =SUM(H30:H32) -> 2.78208
A35: 6 | B35: Shuttering
B36: Long outer beam | C36: 1 | D36: 4 | E36: 6.1 | G36: 0.45 | H36: =G36*E36*D36*C36 -> 10.98
B37: Short outer beam | C37: 1 | D37: 4 | E37: 5.5 | G37: 0.45 | H37: =G37*E37*D37*C37 -> 9.9
B38: Centre partition beam | C38: 2 | D38: 4 | E38: 1.8 | G38: 0.23 | H38: =G38*E38*D38*C38 -> 3.312
G39: Total | H39: =SUM(H36:H38) -> 24.192
A42: 7 | B42: Brick Work
B43: Outer wall | C43: 1 | D43: 2 | E43: 6.1 | F43: 0.23 | G43: 3 | H43: =G43*F43*E43*D43*C43 -> 8.418
B44: Outer wall | C44: 1 | D44: 2 | E44: 5.5 | F44: 0.23 | G44: 3 | H44: =G44*F44*E44*D44*C44 -> 7.59
B45: Centre wall | C45: 1 | D45: 4 | E45: 1.6 | F45: 0.23 | G45: 2 | H45: =G45*F45*E45*D45*C45 -> 2.944
B46: Centre wall | C46: 1 | D46: 4 | E46: 0.45 | F46: 0.23 | G46: 2 | H46: =G46*F46*E46*D46*C46 -> 0.828
B47: Toilet inner | C47: 1 | D47: 1 | E47: 5.64 | F47: 0.23 | G47: 0.2 | H47: =G47*F47*E47*D47*C47 -> 0.25944
B48: Centre partition | C48: 1 | D48: 4 | E48: 1.8 | F48: 0.23 | G48: 0.2 | H48: =G48*F48*E48*D48*C48 -> 0.3312
B49: urinal | C49: 1 | D49: 1 | E49: 5.64 | F49: 0.23 | G49: 0.15 | H49: =G49*F49*E49*D49*C49 -> 0.19458
B50: urinal | C50: 1 | D50: 2 | E50: 0.75 | F50: 0.23 | G50: 0.15 | H50: =G50*F50*E50*D50*C50 -> 0.05175
B51: Steps | C51: 1 | D51: 1 | E51: 1.25 | F51: 0.3 | G51: 0.5 | H51: =G51*F51*E51*D51*C51 -> 0.1875
...

Sheet QUOTATION
A11: PERFORMANCE INVOICE
A12: M/s.DUS Enterprises
A13: NAME OF WORK : CONSTRUCTING OF RESTROOM NEAR FACTORY SHED WITH NECESSARY FACILITIES IN VELLIVOYALCHAVADI UNIT II (CREW WORKSHOP)
A14: To, | C14: Bill No. : 10
A15: M/s. Chennai Radha Engineering Works Pvt Ltd | C15: Work Order No:-
A16: No. 40, Sapthagiri Colony,
A17: Jafferkhanpet, Chennai - 600 083. | C17: Invoice No :-
A18: GSTIN : 33AACCC6068R1Z6 | C18: Invoice date :-
A19: S.No | B19: Description | D19: Amount
A20: 1 | B20: RESTROOM CONSTRUCTION | D20: =ESTIMATE!F30 -> 870555.42
A21: TOTAL AMOUNT | D21: =D20 -> 870555.42
A22: CGST @ 9.00 % | D22: =D21*0.09 -> 78349.987
A23: SGST @ 9.00 % | D23: =D20*0.09 -> 78349.987
A24: TOTAL AMOUNT INCLUDING CGST & SGST | D24: =D21+D22+D23 -> 1027255.4
A25: RUPEES IN WORDS - TEN LAKHS TWENTY SEVEN THOUSAND TWO HUNDERD AND FIFTY FIVE RUPEES ONLY
C26: Signature

Sheet bbs toilet
A1: VVC toilet
A2: SI.NO | B2: Descripition of work | C2: Dia of Rod | D2: NOS | F2: Cutting Length | G2: Total | H2: 8mm | I2: 10mm | J2: 12mm | K2: 16mm
A3: 1 | B3: Plinth beam
B4: Main Rod | C4: 16 | D4: 2 | E4: 6 | F4: 6.6 | G4: =F4*E4*D4 -> 79.2 | K4: =G4 -> 79.2
C5: 16 | D5: 2 | E5: 6 | F5: 6.05 | G5: =F5*E5*D5 -> 72.6 | K5: =G5 -> 72.6
B7: Striupps | C7: 8 | D7: 2 | E7: 61 | F7: 1.06 | G7: =F7*E7*D7 -> 129.32 | H7: =G7 -> 129.32
C8: 8 | D8: 2 | E8: 56 | F8: 1.06 | G8: =F8*E8*D8 -> 118.72 | H8: =G8 -> 118.72
A10: 2 | B10: Tie Beam
C11: 12 | D11: 4 | E11: 4 | F11: 2.2 | G11: =F11*E11*D11 -> 35.2 | J11: =G11 -> 35.2
B12: Striupps
C13: 8 | D13: 4 | E13: 18 | F13: 0.38 | G13: =F13*E13*D13 -> 27.36 | H13: =G13 -> 27.36
B15: Total Length | H15: =SUM(H3:H14) -> 275.4 | I15: =SUM(I3:I14) -> 0 | J15: =SUM(J3:J14) -> 35.2 | K15: =SUM(K3:K14) -> 151.8 | L15: RM
B16: Weight per(kg/m) | H16: =8*8/162 -> 0.39506173 | I16: =10*10/162 -> 0.61728395 | J16: =12*12/162 -> 0.88888889 | K16: =16*16/162 -> 1.5802469 | L16: KG/M
B17: Weight (KG) | H17: =H15*H16 -> 108.8 | I17: =I15*I16 -> 0 | J17: =J15*J16 -> 31.288889 | K17: =K16*K15 -> 239.88148 | L17: KG
B18: Weight (MT) | H18: =SUM(H17:K17)/1000 -> 0.37997037 | L18: MT
